Failed to run detection loop:
 Traceback (most recent call last):
  File "/usr/local/lib/python3.7/dist-packages/PIL/ImageFile.py", line 510, in _save
    fh = fp.fileno()
AttributeError: '_idat' object has no attribute 'fileno'

During handling of the above exception, another exception occurred:

Traceback (most recent call last):
  File "pupper_vision.py", line 70, in main
    image.save(f)
  File "/usr/local/lib/python3.7/dist-packages/PIL/Image.py", line 2151, in save
    save_handler(self, fp, filename)
  File "/usr/local/lib/python3.7/dist-packages/PIL/PngImagePlugin.py", line 1339, in _save
    ImageFile._save(im, _idat(fp, chunk), [("zip", (0, 0) + im.size, 0, rawmode)])
  File "/usr/local/lib/python3.7/dist-packages/PIL/ImageFile.py", line 524, in _save
    l, s, d = e.encode(bufsize)
KeyboardInterrupt

